<?xml version="1.0"?>
<robot name="pusher">

  <material name="blue">
    <color rgba="0 0 0.8 1"/>
  </material>
  <material name="white">
    <color rgba="1 1 1 1"/>
  </material>

  <link name="base">
    <visual>
      <geometry>
        <box size="0.2 0.05 0.05"/>
      </geometry>
    <material name="blue"/>
    </visual>
    <collision>
      <geometry>
        <box size="0.2 0.05 0.05"/>
      </geometry>
    </collision>
    <inertial>
       <mass value="5"/>
       <inertia ixx="0.002" ixy="0.0" ixz="0.0" iyy="0.0178" iyz="0.0" izz="0.0178"/>
    </inertial>
  </link>
  
  <link name="table">
    <visual>
      <geometry>
        <box size="5 5 0.05"/>
      </geometry>
      <origin xyz="0 0 -0.05"/>
    <material name="white"/>
    </visual>
    <collision>
      <geometry>
        <box size="5 5 0.05"/>
      </geometry>
      <origin xyz="0 0 -0.05"/>
    </collision>
  </link>

  <link name="pusher">
    <visual>
      <geometry>
        <cylinder length="0.25" radius="0.01"/>
      </geometry>
      <origin rpy="0 1.57075 0" xyz="0.125 0 0"/>
    </visual>
    <collision>
      <geometry>
        <cylinder length="0.25" radius="0.01"/>
      </geometry>
      <origin rpy="0 1.57075 0" xyz="0.115 0 0"/>
    </collision>
    <inertial>
       <mass value="1"/>
       <origin rpy="0 1.57075 0" xyz="0.115 0 0"/>
       <inertia ixx="0.0" ixy="0.0" ixz="0.0" iyy="0.0052" iyz="0.0" izz="0.0052"/>
    </inertial>
  </link>

  <link name="tip">
    <visual>
      <geometry>
        <sphere radius="0.02"/>
      </geometry>
    <origin xyz="0 0 0"/>
    </visual>
    <collision>
      <geometry>
        <sphere radius="0.02"/>
      </geometry>
    </collision>
    <inertial>
       <mass value="0.1"/>
       <inertia ixx="0.000016" ixy="0.0" ixz="0.0" iyy="0.000016" iyz="0.0" izz="0.000016"/>
    </inertial>
  </link>

  <joint name="base_to_pusher" type="prismatic">
    <parent link="base"/>
    <child link="pusher"/>
    <limit effort="1000.0" lower="-0.05" upper="1.0" velocity="1.0"/>
  </joint>

  <joint name="base_to_table" type="fixed">
    <parent link="base"/>
    <child link="table"/>
  </joint>

  <joint name="pusher_to_tip" type="fixed">
    <parent link="pusher"/>
    <child link="tip"/>
    <origin xyz="0.25 0 0"/>
  </joint>
</robot>
